Workbook

Sheet How to Use
A1: How to Use This Workbook
A3: This workbook is your complete financial model. It tracks revenue, costs, job margins, and cash flow across your entire operation so you can see where money is coming from and where it's going.
A5: Start on the Assumptions tab and update the yellow cells with your numbers -- revenue target, cost percentages, overhead, and cash on hand. Each month, enter actuals in the blue columns on the P&L tab. Log each job on the Job Margins tab. All dashboards update automatically.
A7: Check the Dashboard tab for the big picture: your KPIs, margins, and whether you're on track for the year. The Cash Flow tab shows your 13-week runway so you never get surprised by a cash crunch.
A9: COLOR GUIDE
B10: YELLOW | C10: Your input -- fill these in
B11: BLUE | C11: Actual results -- enter as they come in
B12: GRAY | C12: Calculated -- don't touch
B13: GREEN | C13: Good result -- on track
B14: RED | C14: Needs attention -- action required

Sheet Dashboard
A1: =Assumptions!$B$5&" -- "&Assumptions!$B$6&" Dashboard"
A2: Generated April 22, 2026
A4: THE BOTTOM LINE
A5: Annual Revenue Target | B5: =Assumptions!$B$10
A6: Projected Annual Profit (EBITDA) | B6: =Assumptions!$B$63
A7: Profit Margin % (Gross Margin) | B7: =Assumptions!$B$61
A8: Profit Before Taxes % (EBITDA Margin) | B8: =Assumptions!$B$64
A9: Cash on Hand | B9: =Assumptions!$B$49
A11: KEY PERFORMANCE INDICATORS
A12: Metric | B12: Current | C12: Target | D12: Status
A13: Revenue Year to Date (YTD) | B13: ='P&L'!AY10 | C13: =Assumptions!$B$10 | D13: =IF(OR(B13="",C13=""),"",IF(B13>=C13,"On Track","Below Target"))
A14: Profit Margin % (Gross Margin) | B14: =IF('P&L'!AY10=0,"",'P&L'!AY19/'P&L'!AY10) | C14: =Assumptions!$B$44 | D14: =IF(OR(B14="",C14=""),"",IF(B14>=C14,"On Track","Below Target"))
A15: Profit Before Taxes % (EBITDA) | B15: =IF('P&L'!AY10=0,"",'P&L'!AY38/'P&L'!AY10) | C15: =Assumptions!$B$45 | D15: =IF(OR(B15="",C15=""),"",IF(B15>=C15,"On Track","Below Target"))
A16: Labor as % of Revenue | B16: =IF('P&L'!AY10=0,"",'P&L'!AY13/'P&L'!AY10) | C16: =Assumptions!$B$46 | D16: =IF(OR(B16="",C16=""),"",IF(B16<=C16,"On Track","Above Target"))
A17: Average Job Margin % | B17: ='Job Margins'!I19 | C17: =Assumptions!$B$44 | D17: =IF(OR(B17="",C17=""),"",IF(B17>=C17,"On Track","Below Target"))
A18: Revenue per Technician | B18: =Assumptions!$B$65 | C18: 200000 | D18: =IF(OR(B18="",C18=""),"",IF(B18>=C18,"On Track","Below Target"))
A20: ADDITIONAL METRICS (ENTER MANUALLY)
A21: Backlog (Total Contract Value in Pipeline)
A22: Bid Close Rate %
A23: Accounts Receivable Over 60 Days

Sheet Assumptions
A1: Harbor Electric -- 2026 Financial Model: Assumptions
A2: Change any yellow number and the entire workbook updates automatically.
A4: COMPANY INFO
A5: Company Name | B5: Harbor Electric
A6: Fiscal Year | B6: 2026
A7: Number of Technicians | B7: 22
A9: REVENUE
A10: Annual Revenue Target | B10: 5400000
A11: Monthly Revenue Target (Calculated) | B11: =Assumptions!$B$10/12
A12: Revenue Growth Target % | B12: 0.16
A14: Revenue Mix (must total 100%)
A15: Commercial % of Revenue | B15: 0.45
A16: Data Center % of Revenue | B16: 0.35
A17: Residential % of Revenue | B17: 0.1
A18: Service Agreements % of Revenue | B18: 0.1
A20: YOUR COSTS (% OF REVENUE)
A21: Labor % | B21: 0.3
A22: Materials % | B22: 0.25
A23: Subcontractors % | B23: 0.15
A24: Equipment % | B24: 0.03
A25: Total Cost % | B25: =Assumptions!$B$21+Assumptions!$B$22+Assumptions!$B$23+Assumptions!$B$24
A27: MONTHLY OVERHEAD
A28: Rent / Office | B28: 9000
A29: Insurance (GL, WC, Vehicle) | B29: 13500
A30: Vehicle Lease / Fuel | B30: 11250
A31: Tools & Equipment | B31: 4500
A32: Admin Salaries | B32: 22500
A33: Software / IT | B33: 3150
A34: Professional Fees (Legal, Acct) | B34: 3600
A35: Marketing / Biz Dev | B35: 4500
A36: Utilities | B36: 2250
A37: Office Supplies | B37: 1350
A38: Permits & Licenses | B38: 1800
A39: Training & Certifications | B39: 1350
A40: Total Monthly Overhead | B40: =Assumptions!$B$28+Assumptions!$B$29+Assumptions!$B$30+Assumptions!$B$31+Assumptions!$B$32+Assumptions!$B$33+Assumptions!$B$34+Assumptions!$B$35+Assumptions!$B$36+Assumptions!$B$37+Assumptions!$B$38+Assumptions!$B$39
A41: Overhead estimated from industry benchmarks -- update with your actual figures.
A43: YOUR TARGETS
A44: Profit After Direct Costs Target (Gross Margin %) | B44: 0.27
A45: Profit Before Taxes Target (EBITDA %) | B45: 0.08
A46: Max Labor Cost (% of Revenue) | B46: 0.3
...

Sheet P&L
A1: =Assumptions!$B$5&" -- "&Assumptions!$B$6&" Profit & Loss"
B3: Jan | F3: Feb | J3: Mar | N3: Apr | R3: May | V3: Jun | Z3: Jul | AD3: Aug | AH3: Sep | AL3: Oct | AP3: Nov | AT3: Dec | AX3: YEAR TO DATE (YTD)
A4: Line Item | B4: Budget | C4: Actual | D4: Var $ | E4: Var % | F4: Budget | G4: Actual | H4: Var $ | I4: Var % | J4: Budget | K4: Actual | L4: Var $ | M4: Var % | N4: Budget | O4: Actual | P4: Var $ | Q4: Var % | R4: Budget | S4: Actual | T4: Var $ | U4: Var % | V4: Budget | W4: Actual | X4: Var $ | Y4: Var % | Z4: Budget | AA4: Actual | AB4: Var $ | AC4: Var % | AD4: Budget | AE4: Actual | AF4: Var $ | AG4: Var % | AH4: Budget | AI4: Actual | AJ4: Var $ | AK4: Var % | AL4: Budget | AM4: Actual | AN4: Var $ | AO4: Var % | AP4: Budget | AQ4: Actual | AR4: Var $ | AS4: Var % | AT4: Budget | AU4: Actual | AV4: Var $ | AW4: Var % | AX4: Budget | AY4: Actual
A5: REVENUE
A6: Commercial | B6: =Assumptions!$B$10*Assumptions!B55*Assumptions!$B$15 | D6: =IF(C6="","",C6-B6) | E6: =IF(C6="","",IF(B6=0,0,(C6-B6)/ABS(B6))) | F6: =Assumptions!$B$10*Assumptions!C55*Assumptions!$B$15 | H6: =IF(G6="","",G6-F6) | I6: =IF(G6="","",IF(F6=0,0,(G6-F6)/ABS(F6))) | J6: =Assumptions!$B$10*Assumptions!D55*Assumptions!$B$15 | L6: =IF(K6="","",K6-J6) | M6: =IF(K6="","",IF(J6=0,0,(K6-J6)/ABS(J6))) | N6: =Assumptions!$B$10*Assumptions!E55*Assumptions!$B$15 | P6: =IF(O6="","",O6-N6) | Q6: =IF(O6="","",IF(N6=0,0,(O6-N6)/ABS(N6))) | R6: =Assumptions!$B$10*Assumptions!F55*Assumptions!$B$15 | T6: =IF(S6="","",S6-R6) | U6: =IF(S6="","",IF(R6=0,0,(S6-R6)/ABS(R6))) | V6: =Assumptions!$B$10*Assumptions!G55*Assumptions!$B$15 | X6: =IF(W6="","",W6-V6) | Y6: =IF(W6="","",IF(V6=0,0,(W6-V6)/ABS(V6))) | Z6: =Assumptions!$B$10*Assumptions!H55*Assumptions!$B$15 | AB6: =IF(AA6="","",AA6-Z6) | AC6: =IF(AA6="","",IF(Z6=0,0,(AA6-Z6)/ABS(Z6))) | AD6: =Assumptions!$B$10*Assumptions!I55*Assumptions!$B$15 | AF6: =IF(AE6="","",AE6-AD6) | AG6: =IF(AE6="","",IF(AD6=0,0,(AE6-AD6)/ABS(AD6))) | AH6: =Assumptions!$B$10*Assumptions!J55*Assumptions!$B$15 | AJ6: =IF(AI6="","",AI6-AH6) | AK6: =IF(AI6="","",IF(AH6=0,0,(AI6-AH6)/ABS(AH6))) | AL6: =Assumptions!$B$10*Assumptions!K55*Assumptions!$B$15 | AN6: =IF(AM6="","",AM6-AL6) | AO6: =IF(AM6="","",IF(AL6=0,0,(AM6-AL6)/ABS(AL6))) | AP6: =Assumptions!$B$10*Assumptions!L55*Assumptions!$B$15 | AR6: =IF(AQ6="","",AQ6-AP6) | AS6: =IF(AQ6="","",IF(AP6=0,0,(AQ6-AP6)/ABS(AP6))) | AT6: =Assumptions!$B$10*Assumptions!M55*Assumptions!$B$15 | AV6: =IF(AU6="","",AU6-AT6) | AW6: =IF(AU6="","",IF(AT6=0,0,(AU6-AT6)/ABS(AT6))) | AX6: =B6+F6+J6+N6+R6+V6+Z6+AD6+AH6+AL6+AP6+AT6 | AY6: =SUM(C6,G6,K6,O6,S6,W6,AA6,AE6,AI6,AM6,AQ6,AU6)
A7: Data Center | B7: =Assumptions!$B$10*Assumptions!B55*Assumptions!$B$16 | D7: =IF(C7="","",C7-B7) | E7: =IF(C7="","",IF(B7=0,0,(C7-B7)/ABS(B7))) | F7: =Assumptions!$B$10*Assumptions!C55*Assumptions!$B$16 | H7: =IF(G7="","",G7-F7) | I7: =IF(G7="","",IF(F7=0,0,(G7-F7)/ABS(F7))) | J7: =Assumptions!$B$10*Assumptions!D55*Assumptions!$B$16 | L7: =IF(K7="","",K7-J7) | M7: =IF(K7="","",IF(J7=0,0,(K7-J7)/ABS(J7))) | N7: =Assumptions!$B$10*Assumptions!E55*Assumptions!$B$16 | P7: =IF(O7="","",O7-N7) | Q7: =IF(O7="","",IF(N7=0,0,(O7-N7)/ABS(N7))) | R7: =Assumptions!$B$10*Assumptions!F55*Assumptions!$B$16 | T7: =IF(S7="","",S7-R7) | U7: =IF(S7="","",IF(R7=0,0,(S7-R7)/ABS(R7))) | V7: =Assumptions!$B$10*Assumptions!G55*Assumptions!$B$16 | X7: =IF(W7="","",W7-V7) | Y7: =IF(W7="","",IF(V7=0,0,(W7-V7)/ABS(V7))) | Z7: =Assumptions!$B$10*Assumptions!H55*Assumptions!$B$16 | AB7: =IF(AA7="","",AA7-Z7) | AC7: =IF(AA7="","",IF(Z7=0,0,(AA7-Z7)/ABS(Z7))) | AD7: =Assumptions!$B$10*Assumptions!I55*Assumptions!$B$16 | AF7: =IF(AE7="","",AE7-AD7) | AG7: =IF(AE7="","",IF(AD7=0,0,(AE7-AD7)/ABS(AD7))) | AH7: =Assumptions!$B$10*Assumptions!J55*Assumptions!$B$16 | AJ7: =IF(AI7="","",AI7-AH7) | AK7: =IF(AI7="","",IF(AH7=0,0,(AI7-AH7)/ABS(AH7))) | AL7: =Assumptions!$B$10*Assumptions!K55*Assumptions!$B$16 | AN7: =IF(AM7="","",AM7-AL7) | AO7: =IF(AM7="","",IF(AL7=0,0,(AM7-AL7)/ABS(AL7))) | AP7: =Assumptions!$B$10*Assumptions!L55*Assumptions!$B$16 | AR7: =IF(AQ7="","",AQ7-AP7) | AS7: =IF(AQ7="","",IF(AP7=0,0,(AQ7-AP7)/ABS(AP7))) | AT7: =Assumptions!$B$10*Assumptions!M55*Assumptions!$B$16 | AV7: =IF(AU7="","",AU7-AT7) | AW7: =IF(AU7="","",IF(AT7=0,0,(AU7-AT7)/ABS(AT7))) | AX7: =B7+F7+J7+N7+R7+V7+Z7+AD7+AH7+AL7+AP7+AT7 | AY7: =SUM(C7,G7,K7,O7,S7,W7,AA7,AE7,AI7,AM7,AQ7,AU7)
A8: Residential | B8: =Assumptions!$B$10*Assumptions!B55*Assumptions!$B$17 | D8: =IF(C8="","",C8-B8) | E8: =IF(C8="","",IF(B8=0,0,(C8-B8)/ABS(B8))) | F8: =Assumptions!$B$10*Assumptions!C55*Assumptions!$B$17 | H8: =IF(G8="","",G8-F8) | I8: =IF(G8="","",IF(F8=0,0,(G8-F8)/ABS(F8))) | J8: =Assumptions!$B$10*Assumptions!D55*Assumptions!$B$17 | L8: =IF(K8="","",K8-J8) | M8: =IF(K8="","",IF(J8=0,0,(K8-J8)/ABS(J8))) | N8: =Assumptions!$B$10*Assumptions!E55*Assumptions!$B$17 | P8: =IF(O8="","",O8-N8) | Q8: =IF(O8="","",IF(N8=0,0,(O8-N8)/ABS(N8))) | R8: =Assumptions!$B$10*Assumptions!F55*Assumptions!$B$17 | T8: =IF(S8="","",S8-R8) | U8: =IF(S8="","",IF(R8=0,0,(S8-R8)/ABS(R8))) | V8: =Assumptions!$B$10*Assumptions!G55*Assumptions!$B$17 | X8: =IF(W8="","",W8-V8) | Y8: =IF(W8="","",IF(V8=0,0,(W8-V8)/ABS(V8))) | Z8: =Assumptions!$B$10*Assumptions!H55*Assumptions!$B$17 | AB8: =IF(AA8="","",AA8-Z8) | AC8: =IF(AA8="","",IF(Z8=0,0,(AA8-Z8)/ABS(Z8))) | AD8: =Assumptions!$B$10*Assumptions!I55*Assumptions!$B$17 | AF8: =IF(AE8="","",AE8-AD8) | AG8: =IF(AE8="","",IF(AD8=0,0,(AE8-AD8)/ABS(AD8))) | AH8: =Assumptions!$B$10*Assumptions!J55*Assumptions!$B$17 | AJ8: =IF(AI8="","",AI8-AH8) | AK8: =IF(AI8="","",IF(AH8=0,0,(AI8-AH8)/ABS(AH8))) | AL8: =Assumptions!$B$10*Assumptions!K55*Assumptions!$B$17 | AN8: =IF(AM8="","",AM8-AL8) | AO8: =IF(AM8="","",IF(AL8=0,0,(AM8-AL8)/ABS(AL8))) | AP8: =Assumptions!$B$10*Assumptions!L55*Assumptions!$B$17 | AR8: =IF(AQ8="","",AQ8-AP8) | AS8: =IF(AQ8="","",IF(AP8=0,0,(AQ8-AP8)/ABS(AP8))) | AT8: =Assumptions!$B$10*Assumptions!M55*Assumptions!$B$17 | AV8: =IF(AU8="","",AU8-AT8) | AW8: =IF(AU8="","",IF(AT8=0,0,(AU8-AT8)/ABS(AT8))) | AX8: =B8+F8+J8+N8+R8+V8+Z8+AD8+AH8+AL8+AP8+AT8 | AY8: =SUM(C8,G8,K8,O8,S8,W8,AA8,AE8,AI8,AM8,AQ8,AU8)
A9: Service Agreements | B9: =Assumptions!$B$10*Assumptions!B55*Assumptions!$B$18 | D9: =IF(C9="","",C9-B9) | E9: =IF(C9="","",IF(B9=0,0,(C9-B9)/ABS(B9))) | F9: =Assumptions!$B$10*Assumptions!C55*Assumptions!$B$18 | H9: =IF(G9="","",G9-F9) | I9: =IF(G9="","",IF(F9=0,0,(G9-F9)/ABS(F9))) | J9: =Assumptions!$B$10*Assumptions!D55*Assumptions!$B$18 | L9: =IF(K9="","",K9-J9) | M9: =IF(K9="","",IF(J9=0,0,(K9-J9)/ABS(J9))) | N9: =Assumptions!$B$10*Assumptions!E55*Assumptions!$B$18 | P9: =IF(O9="","",O9-N9) | Q9: =IF(O9="","",IF(N9=0,0,(O9-N9)/ABS(N9))) | R9: =Assumptions!$B$10*Assumptions!F55*Assumptions!$B$18 | T9: =IF(S9="","",S9-R9) | U9: =IF(S9="","",IF(R9=0,0,(S9-R9)/ABS(R9))) | V9: =Assumptions!$B$10*Assumptions!G55*Assumptions!$B$18 | X9: =IF(W9="","",W9-V9) | Y9: =IF(W9="","",IF(V9=0,0,(W9-V9)/ABS(V9))) | Z9: =Assumptions!$B$10*Assumptions!H55*Assumptions!$B$18 | AB9: =IF(AA9="","",AA9-Z9) | AC9: =IF(AA9="","",IF(Z9=0,0,(AA9-Z9)/ABS(Z9))) | AD9: =Assumptions!$B$10*Assumptions!I55*Assumptions!$B$18 | AF9: =IF(AE9="","",AE9-AD9) | AG9: =IF(AE9="","",IF(AD9=0,0,(AE9-AD9)/ABS(AD9))) | AH9: =Assumptions!$B$10*Assumptions!J55*Assumptions!$B$18 | AJ9: =IF(AI9="","",AI9-AH9) | AK9: =IF(AI9="","",IF(AH9=0,0,(AI9-AH9)/ABS(AH9))) | AL9: =Assumptions!$B$10*Assumptions!K55*Assumptions!$B$18 | AN9: =IF(AM9="","",AM9-AL9) | AO9: =IF(AM9="","",IF(AL9=0,0,(AM9-AL9)/ABS(AL9))) | AP9: =Assumptions!$B$10*Assumptions!L55*Assumptions!$B$18 | AR9: =IF(AQ9="","",AQ9-AP9) | AS9: =IF(AQ9="","",IF(AP9=0,0,(AQ9-AP9)/ABS(AP9))) | AT9: =Assumptions!$B$10*Assumptions!M55*Assumptions!$B$18 | AV9: =IF(AU9="","",AU9-AT9) | AW9: =IF(AU9="","",IF(AT9=0,0,(AU9-AT9)/ABS(AT9))) | AX9: =B9+F9+J9+N9+R9+V9+Z9+AD9+AH9+AL9+AP9+AT9 | AY9: =SUM(C9,G9,K9,O9,S9,W9,AA9,AE9,AI9,AM9,AQ9,AU9)
A10: TOTAL REVENUE | B10: =B6+B7+B8+B9 | D10: =IF(C10="","",C10-B10) | E10: =IF(C10="","",IF(B10=0,0,(C10-B10)/ABS(B10))) | F10: =F6+F7+F8+F9 | H10: =IF(G10="","",G10-F10) | I10: =IF(G10="","",IF(F10=0,0,(G10-F10)/ABS(F10))) | J10: =J6+J7+J8+J9 | L10: =IF(K10="","",K10-J10) | M10: =IF(K10="","",IF(J10=0,0,(K10-J10)/ABS(J10))) | N10: =N6+N7+N8+N9 | P10: =IF(O10="","",O10-N10) | Q10: =IF(O10="","",IF(N10=0,0,(O10-N10)/ABS(N10))) | R10: =R6+R7+R8+R9 | T10: =IF(S10="","",S10-R10) | U10: =IF(S10="","",IF(R10=0,0,(S10-R10)/ABS(R10))) | V10: =V6+V7+V8+V9 | X10: =IF(W10="","",W10-V10) | Y10: =IF(W10="","",IF(V10=0,0,(W10-V10)/ABS(V10))) | Z10: =Z6+Z7+Z8+Z9 | AB10: =IF(AA10="","",AA10-Z10) | AC10: =IF(AA10="","",IF(Z10=0,0,(AA10-Z10)/ABS(Z10))) | AD10: =AD6+AD7+AD8+AD9 | AF10: =IF(AE10="","",AE10-AD10) | AG10: =IF(AE10="","",IF(AD10=0,0,(AE10-AD10)/ABS(AD10))) | AH10: =AH6+AH7+AH8+AH9 | AJ10: =IF(AI10="","",AI10-AH10) | AK10: =IF(AI10="","",IF(AH10=0,0,(AI10-AH10)/ABS(AH10))) | AL10: =AL6+AL7+AL8+AL9 | AN10: =IF(AM10="","",AM10-AL10) | AO10: =IF(AM10="","",IF(AL10=0,0,(AM10-AL10)/ABS(AL10))) | AP10: =AP6+AP7+AP8+AP9 | AR10: =IF(AQ10="","",AQ10-AP10) | AS10: =IF(AQ10="","",IF(AP10=0,0,(AQ10-AP10)/ABS(AP10))) | AT10: =AT6+AT7+AT8+AT9 | AV10: =IF(AU10="","",AU10-AT10) | AW10: =IF(AU10="","",IF(AT10=0,0,(AU10-AT10)/ABS(AT10))) | AX10: =B10+F10+J10+N10+R10+V10+Z10+AD10+AH10+AL10+AP10+AT10 | AY10: =SUM(C10,G10,K10,O10,S10,W10,AA10,AE10,AI10,AM10,AQ10,AU10)
A12: DIRECT JOB COSTS (COGS)
A13: Direct Labor | B13: =B10*Assumptions!$B$21 | D13: =IF(C13="","",C13-B13) | E13: =IF(C13="","",IF(B13=0,0,(C13-B13)/ABS(B13))) | F13: =F10*Assumptions!$B$21 | H13: =IF(G13="","",G13-F13) | I13: =IF(G13="","",IF(F13=0,0,(G13-F13)/ABS(F13))) | J13: =J10*Assumptions!$B$21 | L13: =IF(K13="","",K13-J13) | M13: =IF(K13="","",IF(J13=0,0,(K13-J13)/ABS(J13))) | N13: =N10*Assumptions!$B$21 | P13: =IF(O13="","",O13-N13) | Q13: =IF(O13="","",IF(N13=0,0,(O13-N13)/ABS(N13))) | R13: =R10*Assumptions!$B$21 | T13: =IF(S13="","",S13-R13) | U13: =IF(S13="","",IF(R13=0,0,(S13-R13)/ABS(R13))) | V13: =V10*Assumptions!$B$21 | X13: =IF(W13="","",W13-V13) | Y13: =IF(W13="","",IF(V13=0,0,(W13-V13)/ABS(V13))) | Z13: =Z10*Assumptions!$B$21 | AB13: =IF(AA13="","",AA13-Z13) | AC13: =IF(AA13="","",IF(Z13=0,0,(AA13-Z13)/ABS(Z13))) | AD13: =AD10*Assumptions!$B$21 | AF13: =IF(AE13="","",AE13-AD13) | AG13: =IF(AE13="","",IF(AD13=0,0,(AE13-AD13)/ABS(AD13))) | AH13: =AH10*Assumptions!$B$21 | AJ13: =IF(AI13="","",AI13-AH13) | AK13: =IF(AI13="","",IF(AH13=0,0,(AI13-AH13)/ABS(AH13))) | AL13: =AL10*Assumptions!$B$21 | AN13: =IF(AM13="","",AM13-AL13) | AO13: =IF(AM13="","",IF(AL13=0,0,(AM13-AL13)/ABS(AL13))) | AP13: =AP10*Assumptions!$B$21 | AR13: =IF(AQ13="","",AQ13-AP13) | AS13: =IF(AQ13="","",IF(AP13=0,0,(AQ13-AP13)/ABS(AP13))) | AT13: =AT10*Assumptions!$B$21 | AV13: =IF(AU13="","",AU13-AT13) | AW13: =IF(AU13="","",IF(AT13=0,0,(AU13-AT13)/ABS(AT13))) | AX13: =B13+F13+J13+N13+R13+V13+Z13+AD13+AH13+AL13+AP13+AT13 | AY13: =SUM(C13,G13,K13,O13,S13,W13,AA13,AE13,AI13,AM13,AQ13,AU13)
A14: Materials | B14: =B10*Assumptions!$B$22 | D14: =IF(C14="","",C14-B14) | E14: =IF(C14="","",IF(B14=0,0,(C14-B14)/ABS(B14))) | F14: =F10*Assumptions!$B$22 | H14: =IF(G14="","",G14-F14) | I14: =IF(G14="","",IF(F14=0,0,(G14-F14)/ABS(F14))) | J14: =J10*Assumptions!$B$22 | L14: =IF(K14="","",K14-J14) | M14: =IF(K14="","",IF(J14=0,0,(K14-J14)/ABS(J14))) | N14: =N10*Assumptions!$B$22 | P14: =IF(O14="","",O14-N14) | Q14: =IF(O14="","",IF(N14=0,0,(O14-N14)/ABS(N14))) | R14: =R10*Assumptions!$B$22 | T14: =IF(S14="","",S14-R14) | U14: =IF(S14="","",IF(R14=0,0,(S14-R14)/ABS(R14))) | V14: =V10*Assumptions!$B$22 | X14: =IF(W14="","",W14-V14) | Y14: =IF(W14="","",IF(V14=0,0,(W14-V14)/ABS(V14))) | Z14: =Z10*Assumptions!$B$22 | AB14: =IF(AA14="","",AA14-Z14) | AC14: =IF(AA14="","",IF(Z14=0,0,(AA14-Z14)/ABS(Z14))) | AD14: =AD10*Assumptions!$B$22 | AF14: =IF(AE14="","",AE14-AD14) | AG14: =IF(AE14="","",IF(AD14=0,0,(AE14-AD14)/ABS(AD14))) | AH14: =AH10*Assumptions!$B$22 | AJ14: =IF(AI14="","",AI14-AH14) | AK14: =IF(AI14="","",IF(AH14=0,0,(AI14-AH14)/ABS(AH14))) | AL14: =AL10*Assumptions!$B$22 | AN14: =IF(AM14="","",AM14-AL14) | AO14: =IF(AM14="","",IF(AL14=0,0,(AM14-AL14)/ABS(AL14))) | AP14: =AP10*Assumptions!$B$22 | AR14: =IF(AQ14="","",AQ14-AP14) | AS14: =IF(AQ14="","",IF(AP14=0,0,(AQ14-AP14)/ABS(AP14))) | AT14: =AT10*Assumptions!$B$22 | AV14: =IF(AU14="","",AU14-AT14) | AW14: =IF(AU14="","",IF(AT14=0,0,(AU14-AT14)/ABS(AT14))) | AX14: =B14+F14+J14+N14+R14+V14+Z14+AD14+AH14+AL14+AP14+AT14 | AY14: =SUM(C14,G14,K14,O14,S14,W14,AA14,AE14,AI14,AM14,AQ14,AU14)
A15: Subcontractors | B15: =B10*Assumptions!$B$23 | D15: =IF(C15="","",C15-B15) | E15: =IF(C15="","",IF(B15=0,0,(C15-B15)/ABS(B15))) | F15: =F10*Assumptions!$B$23 | H15: =IF(G15="","",G15-F15) | I15: =IF(G15="","",IF(F15=0,0,(G15-F15)/ABS(F15))) | J15: =J10*Assumptions!$B$23 | L15: =IF(K15="","",K15-J15) | M15: =IF(K15="","",IF(J15=0,0,(K15-J15)/ABS(J15))) | N15: =N10*Assumptions!$B$23 | P15: =IF(O15="","",O15-N15) | Q15: =IF(O15="","",IF(N15=0,0,(O15-N15)/ABS(N15))) | R15: =R10*Assumptions!$B$23 | T15: =IF(S15="","",S15-R15) | U15: =IF(S15="","",IF(R15=0,0,(S15-R15)/ABS(R15))) | V15: =V10*Assumptions!$B$23 | X15: =IF(W15="","",W15-V15) | Y15: =IF(W15="","",IF(V15=0,0,(W15-V15)/ABS(V15))) | Z15: =Z10*Assumptions!$B$23 | AB15: =IF(AA15="","",AA15-Z15) | AC15: =IF(AA15="","",IF(Z15=0,0,(AA15-Z15)/ABS(Z15))) | AD15: =AD10*Assumptions!$B$23 | AF15: =IF(AE15="","",AE15-AD15) | AG15: =IF(AE15="","",IF(AD15=0,0,(AE15-AD15)/ABS(AD15))) | AH15: =AH10*Assumptions!$B$23 | AJ15: =IF(AI15="","",AI15-AH15) | AK15: =IF(AI15="","",IF(AH15=0,0,(AI15-AH15)/ABS(AH15))) | AL15: =AL10*Assumptions!$B$23 | AN15: =IF(AM15="","",AM15-AL15) | AO15: =IF(AM15="","",IF(AL15=0,0,(AM15-AL15)/ABS(AL15))) | AP15: =AP10*Assumptions!$B$23 | AR15: =IF(AQ15="","",AQ15-AP15) | AS15: =IF(AQ15="","",IF(AP15=0,0,(AQ15-AP15)/ABS(AP15))) | AT15: =AT10*Assumptions!$B$23 | AV15: =IF(AU15="","",AU15-AT15) | AW15: =IF(AU15="","",IF(AT15=0,0,(AU15-AT15)/ABS(AT15))) | AX15: =B15+F15+J15+N15+R15+V15+Z15+AD15+AH15+AL15+AP15+AT15 | AY15: =SUM(C15,G15,K15,O15,S15,W15,AA15,AE15,AI15,AM15,AQ15,AU15)
A16: Equipment | B16: =B10*Assumptions!$B$24 | D16: =IF(C16="","",C16-B16) | E16: =IF(C16="","",IF(B16=0,0,(C16-B16)/ABS(B16))) | F16: =F10*Assumptions!$B$24 | H16: =IF(G16="","",G16-F16) | I16: =IF(G16="","",IF(F16=0,0,(G16-F16)/ABS(F16))) | J16: =J10*Assumptions!$B$24 | L16: =IF(K16="","",K16-J16) | M16: =IF(K16="","",IF(J16=0,0,(K16-J16)/ABS(J16))) | N16: =N10*Assumptions!$B$24 | P16: =IF(O16="","",O16-N16) | Q16: =IF(O16="","",IF(N16=0,0,(O16-N16)/ABS(N16))) | R16: =R10*Assumptions!$B$24 | T16: =IF(S16="","",S16-R16) | U16: =IF(S16="","",IF(R16=0,0,(S16-R16)/ABS(R16))) | V16: =V10*Assumptions!$B$24 | X16: =IF(W16="","",W16-V16) | Y16: =IF(W16="","",IF(V16=0,0,(W16-V16)/ABS(V16))) | Z16: =Z10*Assumptions!$B$24 | AB16: =IF(AA16="","",AA16-Z16) | AC16: =IF(AA16="","",IF(Z16=0,0,(AA16-Z16)/ABS(Z16))) | AD16: =AD10*Assumptions!$B$24 | AF16: =IF(AE16="","",AE16-AD16) | AG16: =IF(AE16="","",IF(AD16=0,0,(AE16-AD16)/ABS(AD16))) | AH16: =AH10*Assumptions!$B$24 | AJ16: =IF(AI16="","",AI16-AH16) | AK16: =IF(AI16="","",IF(AH16=0,0,(AI16-AH16)/ABS(AH16))) | AL16: =AL10*Assumptions!$B$24 | AN16: =IF(AM16="","",AM16-AL16) | AO16: =IF(AM16="","",IF(AL16=0,0,(AM16-AL16)/ABS(AL16))) | AP16: =AP10*Assumptions!$B$24 | AR16: =IF(AQ16="","",AQ16-AP16) | AS16: =IF(AQ16="","",IF(AP16=0,0,(AQ16-AP16)/ABS(AP16))) | AT16: =AT10*Assumptions!$B$24 | AV16: =IF(AU16="","",AU16-AT16) | AW16: =IF(AU16="","",IF(AT16=0,0,(AU16-AT16)/ABS(AT16))) | AX16: =B16+F16+J16+N16+R16+V16+Z16+AD16+AH16+AL16+AP16+AT16 | AY16: =SUM(C16,G16,K16,O16,S16,W16,AA16,AE16,AI16,AM16,AQ16,AU16)
A17: TOTAL DIRECT COSTS (COGS) | B17: =B13+B14+B15+B16 | D17: =IF(C17="","",C17-B17) | E17: =IF(C17="","",IF(B17=0,0,(C17-B17)/ABS(B17))) | F17: =F13+F14+F15+F16 | H17: =IF(G17="","",G17-F17) | I17: =IF(G17="","",IF(F17=0,0,(G17-F17)/ABS(F17))) | J17: =J13+J14+J15+J16 | L17: =IF(K17="","",K17-J17) | M17: =IF(K17="","",IF(J17=0,0,(K17-J17)/ABS(J17))) | N17: =N13+N14+N15+N16 | P17: =IF(O17="","",O17-N17) | Q17: =IF(O17="","",IF(N17=0,0,(O17-N17)/ABS(N17))) | R17: =R13+R14+R15+R16 | T17: =IF(S17="","",S17-R17) | U17: =IF(S17="","",IF(R17=0,0,(S17-R17)/ABS(R17))) | V17: =V13+V14+V15+V16 | X17: =IF(W17="","",W17-V17) | Y17: =IF(W17="","",IF(V17=0,0,(W17-V17)/ABS(V17))) | Z17: =Z13+Z14+Z15+Z16 | AB17: =IF(AA17="","",AA17-Z17) | AC17: =IF(AA17="","",IF(Z17=0,0,(AA17-Z17)/ABS(Z17))) | AD17: =AD13+AD14+AD15+AD16 | AF17: =IF(AE17="","",AE17-AD17) | AG17: =IF(AE17="","",IF(AD17=0,0,(AE17-AD17)/ABS(AD17))) | AH17: =AH13+AH14+AH15+AH16 | AJ17: =IF(AI17="","",AI17-AH17) | AK17: =IF(AI17="","",IF(AH17=0,0,(AI17-AH17)/ABS(AH17))) | AL17: =AL13+AL14+AL15+AL16 | AN17: =IF(AM17="","",AM17-AL17) | AO17: =IF(AM17="","",IF(AL17=0,0,(AM17-AL17)/ABS(AL17))) | AP17: =AP13+AP14+AP15+AP16 | AR17: =IF(AQ17="","",AQ17-AP17) | AS17: =IF(AQ17="","",IF(AP17=0,0,(AQ17-AP17)/ABS(AP17))) | AT17: =AT13+AT14+AT15+AT16 | AV17: =IF(AU17="","",AU17-AT17) | AW17: =IF(AU17="","",IF(AT17=0,0,(AU17-AT17)/ABS(AT17))) | AX17: =B17+F17+J17+N17+R17+V17+Z17+AD17+AH17+AL17+AP17+AT17 | AY17: =SUM(C17,G17,K17,O17,S17,W17,AA17,AE17,AI17,AM17,AQ17,AU17)
A19: PROFIT AFTER DIRECT COSTS (GROSS PROFIT) | B19: =B10-B17 | D19: =IF(C19="","",C19-B19) | E19: =IF(C19="","",IF(B19=0,0,(C19-B19)/ABS(B19))) | F19: =F10-F17 | H19: =IF(G19="","",G19-F19) | I19: =IF(G19="","",IF(F19=0,0,(G19-F19)/ABS(F19))) | J19: =J10-J17 | L19: =IF(K19="","",K19-J19) | M19: =IF(K19="","",IF(J19=0,0,(K19-J19)/ABS(J19))) | N19: =N10-N17 | P19: =IF(O19="","",O19-N19) | Q19: =IF(O19="","",IF(N19=0,0,(O19-N19)/ABS(N19))) | R19: =R10-R17 | T19: =IF(S19="","",S19-R19) | U19: =IF(S19="","",IF(R19=0,0,(S19-R19)/ABS(R19))) | V19: =V10-V17 | X19: =IF(W19="","",W19-V19) | Y19: =IF(W19="","",IF(V19=0,0,(W19-V19)/ABS(V19))) | Z19: =Z10-Z17 | AB19: =IF(AA19="","",AA19-Z19) | AC19: =IF(AA19="","",IF(Z19=0,0,(AA19-Z19)/ABS(Z19))) | AD19: =AD10-AD17 | AF19: =IF(AE19="","",AE19-AD19) | AG19: =IF(AE19="","",IF(AD19=0,0,(AE19-AD19)/ABS(AD19))) | AH19: =AH10-AH17 | AJ19: =IF(AI19="","",AI19-AH19) | AK19: =IF(AI19="","",IF(AH19=0,0,(AI19-AH19)/ABS(AH19))) | AL19: =AL10-AL17 | AN19: =IF(AM19="","",AM19-AL19) | AO19: =IF(AM19="","",IF(AL19=0,0,(AM19-AL19)/ABS(AL19))) | AP19: =AP10-AP17 | AR19: =IF(AQ19="","",AQ19-AP19) | AS19: =IF(AQ19="","",IF(AP19=0,0,(AQ19-AP19)/ABS(AP19))) | AT19: =AT10-AT17 | AV19: =IF(AU19="","",AU19-AT19) | AW19: =IF(AU19="","",IF(AT19=0,0,(AU19-AT19)/ABS(AT19))) | AX19: =B19+F19+J19+N19+R19+V19+Z19+AD19+AH19+AL19+AP19+AT19 | AY19: =SUM(C19,G19,K19,O19,S19,W19,AA19,AE19,AI19,AM19,AQ19,AU19)
A20: Profit Margin % (Gross Margin) | B20: =IF(B10=0,0,B19/B10) | D20: =IF(C20="","",C20-B20) | E20: =IF(C20="","",IF(B20=0,0,(C20-B20)/ABS(B20))) | F20: =IF(F10=0,0,F19/F10) | H20: =IF(G20="","",G20-F20) | I20: =IF(G20="","",IF(F20=0,0,(G20-F20)/ABS(F20))) | J20: =IF(J10=0,0,J19/J10) | L20: =IF(K20="","",K20-J20) | M20: =IF(K20="","",IF(J20=0,0,(K20-J20)/ABS(J20))) | N20: =IF(N10=0,0,N19/N10) | P20: =IF(O20="","",O20-N20) | Q20: =IF(O20="","",IF(N20=0,0,(O20-N20)/ABS(N20))) | R20: =IF(R10=0,0,R19/R10) | T20: =IF(S20="","",S20-R20) | U20: =IF(S20="","",IF(R20=0,0,(S20-R20)/ABS(R20))) | V20: =IF(V10=0,0,V19/V10) | X20: =IF(W20="","",W20-V20) | Y20: =IF(W20="","",IF(V20=0,0,(W20-V20)/ABS(V20))) | Z20: =IF(Z10=0,0,Z19/Z10) | AB20: =IF(AA20="","",AA20-Z20) | AC20: =IF(AA20="","",IF(Z20=0,0,(AA20-Z20)/ABS(Z20))) | AD20: =IF(AD10=0,0,AD19/AD10) | AF20: =IF(AE20="","",AE20-AD20) | AG20: =IF(AE20="","",IF(AD20=0,0,(AE20-AD20)/ABS(AD20))) | AH20: =IF(AH10=0,0,AH19/AH10) | AJ20: =IF(AI20="","",AI20-AH20) | AK20: =IF(AI20="","",IF(AH20=0,0,(AI20-AH20)/ABS(AH20))) | AL20: =IF(AL10=0,0,AL19/AL10) | AN20: =IF(AM20="","",AM20-AL20) | AO20: =IF(AM20="","",IF(AL20=0,0,(AM20-AL20)/ABS(AL20))) | AP20: =IF(AP10=0,0,AP19/AP10) | AR20: =IF(AQ20="","",AQ20-AP20) | AS20: =IF(AQ20="","",IF(AP20=0,0,(AQ20-AP20)/ABS(AP20))) | AT20: =IF(AT10=0,0,AT19/AT10) | AV20: =IF(AU20="","",AU20-AT20) | AW20: =IF(AU20="","",IF(AT20=0,0,(AU20-AT20)/ABS(AT20))) | AX20: =B20+F20+J20+N20+R20+V20+Z20+AD20+AH20+AL20+AP20+AT20 | AY20: =SUM(C20,G20,K20,O20,S20,W20,AA20,AE20,AI20,AM20,AQ20,AU20)
A22: OVERHEAD
A23: Rent / Office | B23: =Assumptions!$B$28 | D23: =IF(C23="","",C23-B23) | E23: =IF(C23="","",IF(B23=0,0,(C23-B23)/ABS(B23))) | F23: =Assumptions!$B$28 | H23: =IF(G23="","",G23-F23) | I23: =IF(G23="","",IF(F23=0,0,(G23-F23)/ABS(F23))) | J23: =Assumptions!$B$28 | L23: =IF(K23="","",K23-J23) | M23: =IF(K23="","",IF(J23=0,0,(K23-J23)/ABS(J23))) | N23: =Assumptions!$B$28 | P23: =IF(O23="","",O23-N23) | Q23: =IF(O23="","",IF(N23=0,0,(O23-N23)/ABS(N23))) | R23: =Assumptions!$B$28 | T23: =IF(S23="","",S23-R23) | U23: =IF(S23="","",IF(R23=0,0,(S23-R23)/ABS(R23))) | V23: =Assumptions!$B$28 | X23: =IF(W23="","",W23-V23) | Y23: =IF(W23="","",IF(V23=0,0,(W23-V23)/ABS(V23))) | Z23: =Assumptions!$B$28 | AB23: =IF(AA23="","",AA23-Z23) | AC23: =IF(AA23="","",IF(Z23=0,0,(AA23-Z23)/ABS(Z23))) | AD23: =Assumptions!$B$28 | AF23: =IF(AE23="","",AE23-AD23) | AG23: =IF(AE23="","",IF(AD23=0,0,(AE23-AD23)/ABS(AD23))) | AH23: =Assumptions!$B$28 | AJ23: =IF(AI23="","",AI23-AH23) | AK23: =IF(AI23="","",IF(AH23=0,0,(AI23-AH23)/ABS(AH23))) | AL23: =Assumptions!$B$28 | AN23: =IF(AM23="","",AM23-AL23) | AO23: =IF(AM23="","",IF(AL23=0,0,(AM23-AL23)/ABS(AL23))) | AP23: =Assumptions!$B$28 | AR23: =IF(AQ23="","",AQ23-AP23) | AS23: =IF(AQ23="","",IF(AP23=0,0,(AQ23-AP23)/ABS(AP23))) | AT23: =Assumptions!$B$28 | AV23: =IF(AU23="","",AU23-AT23) | AW23: =IF(AU23="","",IF(AT23=0,0,(AU23-AT23)/ABS(AT23))) | AX23: =B23+F23+J23+N23+R23+V23+Z23+AD23+AH23+AL23+AP23+AT23 | AY23: =SUM(C23,G23,K23,O23,S23,W23,AA23,AE23,AI23,AM23,AQ23,AU23)
A24: Insurance (GL, WC, Vehicle) | B24: =Assumptions!$B$29 | D24: =IF(C24="","",C24-B24) | E24: =IF(C24="","",IF(B24=0,0,(C24-B24)/ABS(B24))) | F24: =Assumptions!$B$29 | H24: =IF(G24="","",G24-F24) | I24: =IF(G24="","",IF(F24=0,0,(G24-F24)/ABS(F24))) | J24: =Assumptions!$B$29 | L24: =IF(K24="","",K24-J24) | M24: =IF(K24="","",IF(J24=0,0,(K24-J24)/ABS(J24))) | N24: =Assumptions!$B$29 | P24: =IF(O24="","",O24-N24) | Q24: =IF(O24="","",IF(N24=0,0,(O24-N24)/ABS(N24))) | R24: =Assumptions!$B$29 | T24: =IF(S24="","",S24-R24) | U24: =IF(S24="","",IF(R24=0,0,(S24-R24)/ABS(R24))) | V24: =Assumptions!$B$29 | X24: =IF(W24="","",W24-V24) | Y24: =IF(W24="","",IF(V24=0,0,(W24-V24)/ABS(V24))) | Z24: =Assumptions!$B$29 | AB24: =IF(AA24="","",AA24-Z24) | AC24: =IF(AA24="","",IF(Z24=0,0,(AA24-Z24)/ABS(Z24))) | AD24: =Assumptions!$B$29 | AF24: =IF(AE24="","",AE24-AD24) | AG24: =IF(AE24="","",IF(AD24=0,0,(AE24-AD24)/ABS(AD24))) | AH24: =Assumptions!$B$29 | AJ24: =IF(AI24="","",AI24-AH24) | AK24: =IF(AI24="","",IF(AH24=0,0,(AI24-AH24)/ABS(AH24))) | AL24: =Assumptions!$B$29 | AN24: =IF(AM24="","",AM24-AL24) | AO24: =IF(AM24="","",IF(AL24=0,0,(AM24-AL24)/ABS(AL24))) | AP24: =Assumptions!$B$29 | AR24: =IF(AQ24="","",AQ24-AP24) | AS24: =IF(AQ24="","",IF(AP24=0,0,(AQ24-AP24)/ABS(AP24))) | AT24: =Assumptions!$B$29 | AV24: =IF(AU24="","",AU24-AT24) | AW24: =IF(AU24="","",IF(AT24=0,0,(AU24-AT24)/ABS(AT24))) | AX24: =B24+F24+J24+N24+R24+V24+Z24+AD24+AH24+AL24+AP24+AT24 | AY24: =SUM(C24,G24,K24,O24,S24,W24,AA24,AE24,AI24,AM24,AQ24,AU24)
A25: Vehicle Lease / Fuel | B25: =Assumptions!$B$30 | D25: =IF(C25="","",C25-B25) | E25: =IF(C25="","",IF(B25=0,0,(C25-B25)/ABS(B25))) | F25: =Assumptions!$B$30 | H25: =IF(G25="","",G25-F25) | I25: =IF(G25="","",IF(F25=0,0,(G25-F25)/ABS(F25))) | J25: =Assumptions!$B$30 | L25: =IF(K25="","",K25-J25) | M25: =IF(K25="","",IF(J25=0,0,(K25-J25)/ABS(J25))) | N25: =Assumptions!$B$30 | P25: =IF(O25="","",O25-N25) | Q25: =IF(O25="","",IF(N25=0,0,(O25-N25)/ABS(N25))) | R25: =Assumptions!$B$30 | T25: =IF(S25="","",S25-R25) | U25: =IF(S25="","",IF(R25=0,0,(S25-R25)/ABS(R25))) | V25: =Assumptions!$B$30 | X25: =IF(W25="","",W25-V25) | Y25: =IF(W25="","",IF(V25=0,0,(W25-V25)/ABS(V25))) | Z25: =Assumptions!$B$30 | AB25: =IF(AA25="","",AA25-Z25) | AC25: =IF(AA25="","",IF(Z25=0,0,(AA25-Z25)/ABS(Z25))) | AD25: =Assumptions!$B$30 | AF25: =IF(AE25="","",AE25-AD25) | AG25: =IF(AE25="","",IF(AD25=0,0,(AE25-AD25)/ABS(AD25))) | AH25: =Assumptions!$B$30 | AJ25: =IF(AI25="","",AI25-AH25) | AK25: =IF(AI25="","",IF(AH25=0,0,(AI25-AH25)/ABS(AH25))) | AL25: =Assumptions!$B$30 | AN25: =IF(AM25="","",AM25-AL25) | AO25: =IF(AM25="","",IF(AL25=0,0,(AM25-AL25)/ABS(AL25))) | AP25: =Assumptions!$B$30 | AR25: =IF(AQ25="","",AQ25-AP25) | AS25: =IF(AQ25="","",IF(AP25=0,0,(AQ25-AP25)/ABS(AP25))) | AT25: =Assumptions!$B$30 | AV25: =IF(AU25="","",AU25-AT25) | AW25: =IF(AU25="","",IF(AT25=0,0,(AU25-AT25)/ABS(AT25))) | AX25: =B25+F25+J25+N25+R25+V25+Z25+AD25+AH25+AL25+AP25+AT25 | AY25: =SUM(C25,G25,K25,O25,S25,W25,AA25,AE25,AI25,AM25,AQ25,AU25)
A26: Tools & Equipment | B26: =Assumptions!$B$31 | D26: =IF(C26="","",C26-B26) | E26: =IF(C26="","",IF(B26=0,0,(C26-B26)/ABS(B26))) | F26: =Assumptions!$B$31 | H26: =IF(G26="","",G26-F26) | I26: =IF(G26="","",IF(F26=0,0,(G26-F26)/ABS(F26))) | J26: =Assumptions!$B$31 | L26: =IF(K26="","",K26-J26) | M26: =IF(K26="","",IF(J26=0,0,(K26-J26)/ABS(J26))) | N26: =Assumptions!$B$31 | P26: =IF(O26="","",O26-N26) | Q26: =IF(O26="","",IF(N26=0,0,(O26-N26)/ABS(N26))) | R26: =Assumptions!$B$31 | T26: =IF(S26="","",S26-R26) | U26: =IF(S26="","",IF(R26=0,0,(S26-R26)/ABS(R26))) | V26: =Assumptions!$B$31 | X26: =IF(W26="","",W26-V26) | Y26: =IF(W26="","",IF(V26=0,0,(W26-V26)/ABS(V26))) | Z26: =Assumptions!$B$31 | AB26: =IF(AA26="","",AA26-Z26) | AC26: =IF(AA26="","",IF(Z26=0,0,(AA26-Z26)/ABS(Z26))) | AD26: =Assumptions!$B$31 | AF26: =IF(AE26="","",AE26-AD26) | AG26: =IF(AE26="","",IF(AD26=0,0,(AE26-AD26)/ABS(AD26))) | AH26: =Assumptions!$B$31 | AJ26: =IF(AI26="","",AI26-AH26) | AK26: =IF(AI26="","",IF(AH26=0,0,(AI26-AH26)/ABS(AH26))) | AL26: =Assumptions!$B$31 | AN26: =IF(AM26="","",AM26-AL26) | AO26: =IF(AM26="","",IF(AL26=0,0,(AM26-AL26)/ABS(AL26))) | AP26: =Assumptions!$B$31 | AR26: =IF(AQ26="","",AQ26-AP26) | AS26: =IF(AQ26="","",IF(AP26=0,0,(AQ26-AP26)/ABS(AP26))) | AT26: =Assumptions!$B$31 | AV26: =IF(AU26="","",AU26-AT26) | AW26: =IF(AU26="","",IF(AT26=0,0,(AU26-AT26)/ABS(AT26))) | AX26: =B26+F26+J26+N26+R26+V26+Z26+AD26+AH26+AL26+AP26+AT26 | AY26: =SUM(C26,G26,K26,O26,S26,W26,AA26,AE26,AI26,AM26,AQ26,AU26)
A27: Admin Salaries | B27: =Assumptions!$B$32 | D27: =IF(C27="","",C27-B27) | E27: =IF(C27="","",IF(B27=0,0,(C27-B27)/ABS(B27))) | F27: =Assumptions!$B$32 | H27: =IF(G27="","",G27-F27) | I27: =IF(G27="","",IF(F27=0,0,(G27-F27)/ABS(F27))) | J27: =Assumptions!$B$32 | L27: =IF(K27="","",K27-J27) | M27: =IF(K27="","",IF(J27=0,0,(K27-J27)/ABS(J27))) | N27: =Assumptions!$B$32 | P27: =IF(O27="","",O27-N27) | Q27: =IF(O27="","",IF(N27=0,0,(O27-N27)/ABS(N27))) | R27: =Assumptions!$B$32 | T27: =IF(S27="","",S27-R27) | U27: =IF(S27="","",IF(R27=0,0,(S27-R27)/ABS(R27))) | V27: =Assumptions!$B$32 | X27: =IF(W27="","",W27-V27) | Y27: =IF(W27="","",IF(V27=0,0,(W27-V27)/ABS(V27))) | Z27: =Assumptions!$B$32 | AB27: =IF(AA27="","",AA27-Z27) | AC27: =IF(AA27="","",IF(Z27=0,0,(AA27-Z27)/ABS(Z27))) | AD27: =Assumptions!$B$32 | AF27: =IF(AE27="","",AE27-AD27) | AG27: =IF(AE27="","",IF(AD27=0,0,(AE27-AD27)/ABS(AD27))) | AH27: =Assumptions!$B$32 | AJ27: =IF(AI27="","",AI27-AH27) | AK27: =IF(AI27="","",IF(AH27=0,0,(AI27-AH27)/ABS(AH27))) | AL27: =Assumptions!$B$32 | AN27: =IF(AM27="","",AM27-AL27) | AO27: =IF(AM27="","",IF(AL27=0,0,(AM27-AL27)/ABS(AL27))) | AP27: =Assumptions!$B$32 | AR27: =IF(AQ27="","",AQ27-AP27) | AS27: =IF(AQ27="","",IF(AP27=0,0,(AQ27-AP27)/ABS(AP27))) | AT27: =Assumptions!$B$32 | AV27: =IF(AU27="","",AU27-AT27) | AW27: =IF(AU27="","",IF(AT27=0,0,(AU27-AT27)/ABS(AT27))) | AX27: =B27+F27+J27+N27+R27+V27+Z27+AD27+AH27+AL27+AP27+AT27 | AY27: =SUM(C27,G27,K27,O27,S27,W27,AA27,AE27,AI27,AM27,AQ27,AU27)
A28: Software / IT | B28: =Assumptions!$B$33 | D28: =IF(C28="","",C28-B28) | E28: =IF(C28="","",IF(B28=0,0,(C28-B28)/ABS(B28))) | F28: =Assumptions!$B$33 | H28: =IF(G28="","",G28-F28) | I28: =IF(G28="","",IF(F28=0,0,(G28-F28)/ABS(F28))) | J28: =Assumptions!$B$33 | L28: =IF(K28="","",K28-J28) | M28: =IF(K28="","",IF(J28=0,0,(K28-J28)/ABS(J28))) | N28: =Assumptions!$B$33 | P28: =IF(O28="","",O28-N28) | Q28: =IF(O28="","",IF(N28=0,0,(O28-N28)/ABS(N28))) | R28: =Assumptions!$B$33 | T28: =IF(S28="","",S28-R28) | U28: =IF(S28="","",IF(R28=0,0,(S28-R28)/ABS(R28))) | V28: =Assumptions!$B$33 | X28: =IF(W28="","",W28-V28) | Y28: =IF(W28="","",IF(V28=0,0,(W28-V28)/ABS(V28))) | Z28: =Assumptions!$B$33 | AB28: =IF(AA28="","",AA28-Z28) | AC28: =IF(AA28="","",IF(Z28=0,0,(AA28-Z28)/ABS(Z28))) | AD28: =Assumptions!$B$33 | AF28: =IF(AE28="","",AE28-AD28) | AG28: =IF(AE28="","",IF(AD28=0,0,(AE28-AD28)/ABS(AD28))) | AH28: =Assumptions!$B$33 | AJ28: =IF(AI28="","",AI28-AH28) | AK28: =IF(AI28="","",IF(AH28=0,0,(AI28-AH28)/ABS(AH28))) | AL28: =Assumptions!$B$33 | AN28: =IF(AM28="","",AM28-AL28) | AO28: =IF(AM28="","",IF(AL28=0,0,(AM28-AL28)/ABS(AL28))) | AP28: =Assumptions!$B$33 | AR28: =IF(AQ28="","",AQ28-AP28) | AS28: =IF(AQ28="","",IF(AP28=0,0,(AQ28-AP28)/ABS(AP28))) | AT28: =Assumptions!$B$33 | AV28: =IF(AU28="","",AU28-AT28) | AW28: =IF(AU28="","",IF(AT28=0,0,(AU28-AT28)/ABS(AT28))) | AX28: =B28+F28+J28+N28+R28+V28+Z28+AD28+AH28+AL28+AP28+AT28 | AY28: =SUM(C28,G28,K28,O28,S28,W28,AA28,AE28,AI28,AM28,AQ28,AU28)
A29: Professional Fees (Legal, Acct) | B29: =Assumptions!$B$34 | D29: =IF(C29="","",C29-B29) | E29: =IF(C29="","",IF(B29=0,0,(C29-B29)/ABS(B29))) | F29: =Assumptions!$B$34 | H29: =IF(G29="","",G29-F29) | I29: =IF(G29="","",IF(F29=0,0,(G29-F29)/ABS(F29))) | J29: =Assumptions!$B$34 | L29: =IF(K29="","",K29-J29) | M29: =IF(K29="","",IF(J29=0,0,(K29-J29)/ABS(J29))) | N29: =Assumptions!$B$34 | P29: =IF(O29="","",O29-N29) | Q29: =IF(O29="","",IF(N29=0,0,(O29-N29)/ABS(N29))) | R29: =Assumptions!$B$34 | T29: =IF(S29="","",S29-R29) | U29: =IF(S29="","",IF(R29=0,0,(S29-R29)/ABS(R29))) | V29: =Assumptions!$B$34 | X29: =IF(W29="","",W29-V29) | Y29: =IF(W29="","",IF(V29=0,0,(W29-V29)/ABS(V29))) | Z29: =Assumptions!$B$34 | AB29: =IF(AA29="","",AA29-Z29) | AC29: =IF(AA29="","",IF(Z29=0,0,(AA29-Z29)/ABS(Z29))) | AD29: =Assumptions!$B$34 | AF29: =IF(AE29="","",AE29-AD29) | AG29: =IF(AE29="","",IF(AD29=0,0,(AE29-AD29)/ABS(AD29))) | AH29: =Assumptions!$B$34 | AJ29: =IF(AI29="","",AI29-AH29) | AK29: =IF(AI29="","",IF(AH29=0,0,(AI29-AH29)/ABS(AH29))) | AL29: =Assumptions!$B$34 | AN29: =IF(AM29="","",AM29-AL29) | AO29: =IF(AM29="","",IF(AL29=0,0,(AM29-AL29)/ABS(AL29))) | AP29: =Assumptions!$B$34 | AR29: =IF(AQ29="","",AQ29-AP29) | AS29: =IF(AQ29="","",IF(AP29=0,0,(AQ29-AP29)/ABS(AP29))) | AT29: =Assumptions!$B$34 | AV29: =IF(AU29="","",AU29-AT29) | AW29: =IF(AU29="","",IF(AT29=0,0,(AU29-AT29)/ABS(AT29))) | AX29: =B29+F29+J29+N29+R29+V29+Z29+AD29+AH29+AL29+AP29+AT29 | AY29: =SUM(C29,G29,K29,O29,S29,W29,AA29,AE29,AI29,AM29,AQ29,AU29)
A30: Marketing / Biz Dev | B30: =Assumptions!$B$35 | D30: =IF(C30="","",C30-B30) | E30: =IF(C30="","",IF(B30=0,0,(C30-B30)/ABS(B30))) | F30: =Assumptions!$B$35 | H30: =IF(G30="","",G30-F30) | I30: =IF(G30="","",IF(F30=0,0,(G30-F30)/ABS(F30))) | J30: =Assumptions!$B$35 | L30: =IF(K30="","",K30-J30) | M30: =IF(K30="","",IF(J30=0,0,(K30-J30)/ABS(J30))) | N30: =Assumptions!$B$35 | P30: =IF(O30="","",O30-N30) | Q30: =IF(O30="","",IF(N30=0,0,(O30-N30)/ABS(N30))) | R30: =Assumptions!$B$35 | T30: =IF(S30="","",S30-R30) | U30: =IF(S30="","",IF(R30=0,0,(S30-R30)/ABS(R30))) | V30: =Assumptions!$B$35 | X30: =IF(W30="","",W30-V30) | Y30: =IF(W30="","",IF(V30=0,0,(W30-V30)/ABS(V30))) | Z30: =Assumptions!$B$35 | AB30: =IF(AA30="","",AA30-Z30) | AC30: =IF(AA30="","",IF(Z30=0,0,(AA30-Z30)/ABS(Z30))) | AD30: =Assumptions!$B$35 | AF30: =IF(AE30="","",AE30-AD30) | AG30: =IF(AE30="","",IF(AD30=0,0,(AE30-AD30)/ABS(AD30))) | AH30: =Assumptions!$B$35 | AJ30: =IF(AI30="","",AI30-AH30) | AK30: =IF(AI30="","",IF(AH30=0,0,(AI30-AH30)/ABS(AH30))) | AL30: =Assumptions!$B$35 | AN30: =IF(AM30="","",AM30-AL30) | AO30: =IF(AM30="","",IF(AL30=0,0,(AM30-AL30)/ABS(AL30))) | AP30: =Assumptions!$B$35 | AR30: =IF(AQ30="","",AQ30-AP30) | AS30: =IF(AQ30="","",IF(AP30=0,0,(AQ30-AP30)/ABS(AP30))) | AT30: =Assumptions!$B$35 | AV30: =IF(AU30="","",AU30-AT30) | AW30: =IF(AU30="","",IF(AT30=0,0,(AU30-AT30)/ABS(AT30))) | AX30: =B30+F30+J30+N30+R30+V30+Z30+AD30+AH30+AL30+AP30+AT30 | AY30: =SUM(C30,G30,K30,O30,S30,W30,AA30,AE30,AI30,AM30,AQ30,AU30)
A31: Utilities | B31: =Assumptions!$B$36 | D31: =IF(C31="","",C31-B31) | E31: =IF(C31="","",IF(B31=0,0,(C31-B31)/ABS(B31))) | F31: =Assumptions!$B$36 | H31: =IF(G31="","",G31-F31) | I31: =IF(G31="","",IF(F31=0,0,(G31-F31)/ABS(F31))) | J31: =Assumptions!$B$36 | L31: =IF(K31="","",K31-J31) | M31: =IF(K31="","",IF(J31=0,0,(K31-J31)/ABS(J31))) | N31: =Assumptions!$B$36 | P31: =IF(O31="","",O31-N31) | Q31: =IF(O31="","",IF(N31=0,0,(O31-N31)/ABS(N31))) | R31: =Assumptions!$B$36 | T31: =IF(S31="","",S31-R31) | U31: =IF(S31="","",IF(R31=0,0,(S31-R31)/ABS(R31))) | V31: =Assumptions!$B$36 | X31: =IF(W31="","",W31-V31) | Y31: =IF(W31="","",IF(V31=0,0,(W31-V31)/ABS(V31))) | Z31: =Assumptions!$B$36 | AB31: =IF(AA31="","",AA31-Z31) | AC31: =IF(AA31="","",IF(Z31=0,0,(AA31-Z31)/ABS(Z31))) | AD31: =Assumptions!$B$36 | AF31: =IF(AE31="","",AE31-AD31) | AG31: =IF(AE31="","",IF(AD31=0,0,(AE31-AD31)/ABS(AD31))) | AH31: =Assumptions!$B$36 | AJ31: =IF(AI31="","",AI31-AH31) | AK31: =IF(AI31="","",IF(AH31=0,0,(AI31-AH31)/ABS(AH31))) | AL31: =Assumptions!$B$36 | AN31: =IF(AM31="","",AM31-AL31) | AO31: =IF(AM31="","",IF(AL31=0,0,(AM31-AL31)/ABS(AL31))) | AP31: =Assumptions!$B$36 | AR31: =IF(AQ31="","",AQ31-AP31) | AS31: =IF(AQ31="","",IF(AP31=0,0,(AQ31-AP31)/ABS(AP31))) | AT31: =Assumptions!$B$36 | AV31: =IF(AU31="","",AU31-AT31) | AW31: =IF(AU31="","",IF(AT31=0,0,(AU31-AT31)/ABS(AT31))) | AX31: =B31+F31+J31+N31+R31+V31+Z31+AD31+AH31+AL31+AP31+AT31 | AY31: =SUM(C31,G31,K31,O31,S31,W31,AA31,AE31,AI31,AM31,AQ31,AU31)
A32: Office Supplies | B32: =Assumptions!$B$37 | D32: =IF(C32="","",C32-B32) | E32: =IF(C32="","",IF(B32=0,0,(C32-B32)/ABS(B32))) | F32: =Assumptions!$B$37 | H32: =IF(G32="","",G32-F32) | I32: =IF(G32="","",IF(F32=0,0,(G32-F32)/ABS(F32))) | J32: =Assumptions!$B$37 | L32: =IF(K32="","",K32-J32) | M32: =IF(K32="","",IF(J32=0,0,(K32-J32)/ABS(J32))) | N32: =Assumptions!$B$37 | P32: =IF(O32="","",O32-N32) | Q32: =IF(O32="","",IF(N32=0,0,(O32-N32)/ABS(N32))) | R32: =Assumptions!$B$37 | T32: =IF(S32="","",S32-R32) | U32: =IF(S32="","",IF(R32=0,0,(S32-R32)/ABS(R32))) | V32: =Assumptions!$B$37 | X32: =IF(W32="","",W32-V32) | Y32: =IF(W32="","",IF(V32=0,0,(W32-V32)/ABS(V32))) | Z32: =Assumptions!$B$37 | AB32: =IF(AA32="","",AA32-Z32) | AC32: =IF(AA32="","",IF(Z32=0,0,(AA32-Z32)/ABS(Z32))) | AD32: =Assumptions!$B$37 | AF32: =IF(AE32="","",AE32-AD32) | AG32: =IF(AE32="","",IF(AD32=0,0,(AE32-AD32)/ABS(AD32))) | AH32: =Assumptions!$B$37 | AJ32: =IF(AI32="","",AI32-AH32) | AK32: =IF(AI32="","",IF(AH32=0,0,(AI32-AH32)/ABS(AH32))) | AL32: =Assumptions!$B$37 | AN32: =IF(AM32="","",AM32-AL32) | AO32: =IF(AM32="","",IF(AL32=0,0,(AM32-AL32)/ABS(AL32))) | AP32: =Assumptions!$B$37 | AR32: =IF(AQ32="","",AQ32-AP32) | AS32: =IF(AQ32="","",IF(AP32=0,0,(AQ32-AP32)/ABS(AP32))) | AT32: =Assumptions!$B$37 | AV32: =IF(AU32="","",AU32-AT32) | AW32: =IF(AU32="","",IF(AT32=0,0,(AU32-AT32)/ABS(AT32))) | AX32: =B32+F32+J32+N32+R32+V32+Z32+AD32+AH32+AL32+AP32+AT32 | AY32: =SUM(C32,G32,K32,O32,S32,W32,AA32,AE32,AI32,AM32,AQ32,AU32)
A33: Permits & Licenses | B33: =Assumptions!$B$38 | D33: =IF(C33="","",C33-B33) | E33: =IF(C33="","",IF(B33=0,0,(C33-B33)/ABS(B33))) | F33: =Assumptions!$B$38 | H33: =IF(G33="","",G33-F33) | I33: =IF(G33="","",IF(F33=0,0,(G33-F33)/ABS(F33))) | J33: =Assumptions!$B$38 | L33: =IF(K33="","",K33-J33) | M33: =IF(K33="","",IF(J33=0,0,(K33-J33)/ABS(J33))) | N33: =Assumptions!$B$38 | P33: =IF(O33="","",O33-N33) | Q33: =IF(O33="","",IF(N33=0,0,(O33-N33)/ABS(N33))) | R33: =Assumptions!$B$38 | T33: =IF(S33="","",S33-R33) | U33: =IF(S33="","",IF(R33=0,0,(S33-R33)/ABS(R33))) | V33: =Assumptions!$B$38 | X33: =IF(W33="","",W33-V33) | Y33: =IF(W33="","",IF(V33=0,0,(W33-V33)/ABS(V33))) | Z33: =Assumptions!$B$38 | AB33: =IF(AA33="","",AA33-Z33) | AC33: =IF(AA33="","",IF(Z33=0,0,(AA33-Z33)/ABS(Z33))) | AD33: =Assumptions!$B$38 | AF33: =IF(AE33="","",AE33-AD33) | AG33: =IF(AE33="","",IF(AD33=0,0,(AE33-AD33)/ABS(AD33))) | AH33: =Assumptions!$B$38 | AJ33: =IF(AI33="","",AI33-AH33) | AK33: =IF(AI33="","",IF(AH33=0,0,(AI33-AH33)/ABS(AH33))) | AL33: =Assumptions!$B$38 | AN33: =IF(AM33="","",AM33-AL33) | AO33: =IF(AM33="","",IF(AL33=0,0,(AM33-AL33)/ABS(AL33))) | AP33: =Assumptions!$B$38 | AR33: =IF(AQ33="","",AQ33-AP33) | AS33: =IF(AQ33="","",IF(AP33=0,0,(AQ33-AP33)/ABS(AP33))) | AT33: =Assumptions!$B$38 | AV33: =IF(AU33="","",AU33-AT33) | AW33: =IF(AU33="","",IF(AT33=0,0,(AU33-AT33)/ABS(AT33))) | AX33: =B33+F33+J33+N33+R33+V33+Z33+AD33+AH33+AL33+AP33+AT33 | AY33: =SUM(C33,G33,K33,O33,S33,W33,AA33,AE33,AI33,AM33,AQ33,AU33)
A34: Training & Certifications | B34: =Assumptions!$B$39 | D34: =IF(C34="","",C34-B34) | E34: =IF(C34="","",IF(B34=0,0,(C34-B34)/ABS(B34))) | F34: =Assumptions!$B$39 | H34: =IF(G34="","",G34-F34) | I34: =IF(G34="","",IF(F34=0,0,(G34-F34)/ABS(F34))) | J34: =Assumptions!$B$39 | L34: =IF(K34="","",K34-J34) | M34: =IF(K34="","",IF(J34=0,0,(K34-J34)/ABS(J34))) | N34: =Assumptions!$B$39 | P34: =IF(O34="","",O34-N34) | Q34: =IF(O34="","",IF(N34=0,0,(O34-N34)/ABS(N34))) | R34: =Assumptions!$B$39 | T34: =IF(S34="","",S34-R34) | U34: =IF(S34="","",IF(R34=0,0,(S34-R34)/ABS(R34))) | V34: =Assumptions!$B$39 | X34: =IF(W34="","",W34-V34) | Y34: =IF(W34="","",IF(V34=0,0,(W34-V34)/ABS(V34))) | Z34: =Assumptions!$B$39 | AB34: =IF(AA34="","",AA34-Z34) | AC34: =IF(AA34="","",IF(Z34=0,0,(AA34-Z34)/ABS(Z34))) | AD34: =Assumptions!$B$39 | AF34: =IF(AE34="","",AE34-AD34) | AG34: =IF(AE34="","",IF(AD34=0,0,(AE34-AD34)/ABS(AD34))) | AH34: =Assumptions!$B$39 | AJ34: =IF(AI34="","",AI34-AH34) | AK34: =IF(AI34="","",IF(AH34=0,0,(AI34-AH34)/ABS(AH34))) | AL34: =Assumptions!$B$39 | AN34: =IF(AM34="","",AM34-AL34) | AO34: =IF(AM34="","",IF(AL34=0,0,(AM34-AL34)/ABS(AL34))) | AP34: =Assumptions!$B$39 | AR34: =IF(AQ34="","",AQ34-AP34) | AS34: =IF(AQ34="","",IF(AP34=0,0,(AQ34-AP34)/ABS(AP34))) | AT34: =Assumptions!$B$39 | AV34: =IF(AU34="","",AU34-AT34) | AW34: =IF(AU34="","",IF(AT34=0,0,(AU34-AT34)/ABS(AT34))) | AX34: =B34+F34+J34+N34+R34+V34+Z34+AD34+AH34+AL34+AP34+AT34 | AY34: =SUM(C34,G34,K34,O34,S34,W34,AA34,AE34,AI34,AM34,AQ34,AU34)
A35: TOTAL OVERHEAD | B35: =B23+B24+B25+B26+B27+B28+B29+B30+B31+B32+B33+B34 | D35: =IF(C35="","",C35-B35) | E35: =IF(C35="","",IF(B35=0,0,(C35-B35)/ABS(B35))) | F35: =F23+F24+F25+F26+F27+F28+F29+F30+F31+F32+F33+F34 | H35: =IF(G35="","",G35-F35) | I35: =IF(G35="","",IF(F35=0,0,(G35-F35)/ABS(F35))) | J35: =J23+J24+J25+J26+J27+J28+J29+J30+J31+J32+J33+J34 | L35: =IF(K35="","",K35-J35) | M35: =IF(K35="","",IF(J35=0,0,(K35-J35)/ABS(J35))) | N35: =N23+N24+N25+N26+N27+N28+N29+N30+N31+N32+N33+N34 | P35: =IF(O35="","",O35-N35) | Q35: =IF(O35="","",IF(N35=0,0,(O35-N35)/ABS(N35))) | R35: =R23+R24+R25+R26+R27+R28+R29+R30+R31+R32+R33+R34 | T35: =IF(S35="","",S35-R35) | U35: =IF(S35="","",IF(R35=0,0,(S35-R35)/ABS(R35))) | V35: =V23+V24+V25+V26+V27+V28+V29+V30+V31+V32+V33+V34 | X35: =IF(W35="","",W35-V35) | Y35: =IF(W35="","",IF(V35=0,0,(W35-V35)/ABS(V35))) | Z35: =Z23+Z24+Z25+Z26+Z27+Z28+Z29+Z30+Z31+Z32+Z33+Z34 | AB35: =IF(AA35="","",AA35-Z35) | AC35: =IF(AA35="","",IF(Z35=0,0,(AA35-Z35)/ABS(Z35))) | AD35: =AD23+AD24+AD25+AD26+AD27+AD28+AD29+AD30+AD31+AD32+AD33+AD34 | AF35: =IF(AE35="","",AE35-AD35) | AG35: =IF(AE35="","",IF(AD35=0,0,(AE35-AD35)/ABS(AD35))) | AH35: =AH23+AH24+AH25+AH26+AH27+AH28+AH29+AH30+AH31+AH32+AH33+AH34 | AJ35: =IF(AI35="","",AI35-AH35) | AK35: =IF(AI35="","",IF(AH35=0,0,(AI35-AH35)/ABS(AH35))) | AL35: =AL23+AL24+AL25+AL26+AL27+AL28+AL29+AL30+AL31+AL32+AL33+AL34 | AN35: =IF(AM35="","",AM35-AL35) | AO35: =IF(AM35="","",IF(AL35=0,0,(AM35-AL35)/ABS(AL35))) | AP35: =AP23+AP24+AP25+AP26+AP27+AP28+AP29+AP30+AP31+AP32+AP33+AP34 | AR35: =IF(AQ35="","",AQ35-AP35) | AS35: =IF(AQ35="","",IF(AP35=0,0,(AQ35-AP35)/ABS(AP35))) | AT35: =AT23+AT24+AT25+AT26+AT27+AT28+AT29+AT30+AT31+AT32+AT33+AT34 | AV35: =IF(AU35="","",AU35-AT35) | AW35: =IF(AU35="","",IF(AT35=0,0,(AU35-AT35)/ABS(AT35))) | AX35: =B35+F35+J35+N35+R35+V35+Z35+AD35+AH35+AL35+AP35+AT35 | AY35: =SUM(C35,G35,K35,O35,S35,W35,AA35,AE35,AI35,AM35,AQ35,AU35)
A36: Overhead as % of Revenue | B36: =IF(B10=0,0,B35/B10) | D36: =IF(C36="","",C36-B36) | E36: =IF(C36="","",IF(B36=0,0,(C36-B36)/ABS(B36))) | F36: =IF(F10=0,0,F35/F10) | H36: =IF(G36="","",G36-F36) | I36: =IF(G36="","",IF(F36=0,0,(G36-F36)/ABS(F36))) | J36: =IF(J10=0,0,J35/J10) | L36: =IF(K36="","",K36-J36) | M36: =IF(K36="","",IF(J36=0,0,(K36-J36)/ABS(J36))) | N36: =IF(N10=0,0,N35/N10) | P36: =IF(O36="","",O36-N36) | Q36: =IF(O36="","",IF(N36=0,0,(O36-N36)/ABS(N36))) | R36: =IF(R10=0,0,R35/R10) | T36: =IF(S36="","",S36-R36) | U36: =IF(S36="","",IF(R36=0,0,(S36-R36)/ABS(R36))) | V36: =IF(V10=0,0,V35/V10) | X36: =IF(W36="","",W36-V36) | Y36: =IF(W36="","",IF(V36=0,0,(W36-V36)/ABS(V36))) | Z36: =IF(Z10=0,0,Z35/Z10) | AB36: =IF(AA36="","",AA36-Z36) | AC36: =IF(AA36="","",IF(Z36=0,0,(AA36-Z36)/ABS(Z36))) | AD36: =IF(AD10=0,0,AD35/AD10) | AF36: =IF(AE36="","",AE36-AD36) | AG36: =IF(AE36="","",IF(AD36=0,0,(AE36-AD36)/ABS(AD36))) | AH36: =IF(AH10=0,0,AH35/AH10) | AJ36: =IF(AI36="","",AI36-AH36) | AK36: =IF(AI36="","",IF(AH36=0,0,(AI36-AH36)/ABS(AH36))) | AL36: =IF(AL10=0,0,AL35/AL10) | AN36: =IF(AM36="","",AM36-AL36) | AO36: =IF(AM36="","",IF(AL36=0,0,(AM36-AL36)/ABS(AL36))) | AP36: =IF(AP10=0,0,AP35/AP10) | AR36: =IF(AQ36="","",AQ36-AP36) | AS36: =IF(AQ36="","",IF(AP36=0,0,(AQ36-AP36)/ABS(AP36))) | AT36: =IF(AT10=0,0,AT35/AT10) | AV36: =IF(AU36="","",AU36-AT36) | AW36: =IF(AU36="","",IF(AT36=0,0,(AU36-AT36)/ABS(AT36))) | AX36: =B36+F36+J36+N36+R36+V36+Z36+AD36+AH36+AL36+AP36+AT36 | AY36: =SUM(C36,G36,K36,O36,S36,W36,AA36,AE36,AI36,AM36,AQ36,AU36)
A38: PROFIT BEFORE TAXES (EBITDA) | B38: =B19-B35 | D38: =IF(C38="","",C38-B38) | E38: =IF(C38="","",IF(B38=0,0,(C38-B38)/ABS(B38))) | F38: =F19-F35 | H38: =IF(G38="","",G38-F38) | I38: =IF(G38="","",IF(F38=0,0,(G38-F38)/ABS(F38))) | J38: =J19-J35 | L38: =IF(K38="","",K38-J38) | M38: =IF(K38="","",IF(J38=0,0,(K38-J38)/ABS(J38))) | N38: =N19-N35 | P38: =IF(O38="","",O38-N38) | Q38: =IF(O38="","",IF(N38=0,0,(O38-N38)/ABS(N38))) | R38: =R19-R35 | T38: =IF(S38="","",S38-R38) | U38: =IF(S38="","",IF(R38=0,0,(S38-R38)/ABS(R38))) | V38: =V19-V35 | X38: =IF(W38="","",W38-V38) | Y38: =IF(W38="","",IF(V38=0,0,(W38-V38)/ABS(V38))) | Z38: =Z19-Z35 | AB38: =IF(AA38="","",AA38-Z38) | AC38: =IF(AA38="","",IF(Z38=0,0,(AA38-Z38)/ABS(Z38))) | AD38: =AD19-AD35 | AF38: =IF(AE38="","",AE38-AD38) | AG38: =IF(AE38="","",IF(AD38=0,0,(AE38-AD38)/ABS(AD38))) | AH38: =AH19-AH35 | AJ38: =IF(AI38="","",AI38-AH38) | AK38: =IF(AI38="","",IF(AH38=0,0,(AI38-AH38)/ABS(AH38))) | AL38: =AL19-AL35 | AN38: =IF(AM38="","",AM38-AL38) | AO38: =IF(AM38="","",IF(AL38=0,0,(AM38-AL38)/ABS(AL38))) | AP38: =AP19-AP35 | AR38: =IF(AQ38="","",AQ38-AP38) | AS38: =IF(AQ38="","",IF(AP38=0,0,(AQ38-AP38)/ABS(AP38))) | AT38: =AT19-AT35 | AV38: =IF(AU38="","",AU38-AT38) | AW38: =IF(AU38="","",IF(AT38=0,0,(AU38-AT38)/ABS(AT38))) | AX38: =B38+F38+J38+N38+R38+V38+Z38+AD38+AH38+AL38+AP38+AT38 | AY38: =SUM(C38,G38,K38,O38,S38,W38,AA38,AE38,AI38,AM38,AQ38,AU38)
A39: Profit Before Taxes % (EBITDA Margin) | B39: =IF(B10=0,0,B38/B10) | D39: =IF(C39="","",C39-B39) | E39: =IF(C39="","",IF(B39=0,0,(C39-B39)/ABS(B39))) | F39: =IF(F10=0,0,F38/F10) | H39: =IF(G39="","",G39-F39) | I39: =IF(G39="","",IF(F39=0,0,(G39-F39)/ABS(F39))) | J39: =IF(J10=0,0,J38/J10) | L39: =IF(K39="","",K39-J39) | M39: =IF(K39="","",IF(J39=0,0,(K39-J39)/ABS(J39))) | N39: =IF(N10=0,0,N38/N10) | P39: =IF(O39="","",O39-N39) | Q39: =IF(O39="","",IF(N39=0,0,(O39-N39)/ABS(N39))) | R39: =IF(R10=0,0,R38/R10) | T39: =IF(S39="","",S39-R39) | U39: =IF(S39="","",IF(R39=0,0,(S39-R39)/ABS(R39))) | V39: =IF(V10=0,0,V38/V10) | X39: =IF(W39="","",W39-V39) | Y39: =IF(W39="","",IF(V39=0,0,(W39-V39)/ABS(V39))) | Z39: =IF(Z10=0,0,Z38/Z10) | AB39: =IF(AA39="","",AA39-Z39) | AC39: =IF(AA39="","",IF(Z39=0,0,(AA39-Z39)/ABS(Z39))) | AD39: =IF(AD10=0,0,AD38/AD10) | AF39: =IF(AE39="","",AE39-AD39) | AG39: =IF(AE39="","",IF(AD39=0,0,(AE39-AD39)/ABS(AD39))) | AH39: =IF(AH10=0,0,AH38/AH10) | AJ39: =IF(AI39="","",AI39-AH39) | AK39: =IF(AI39="","",IF(AH39=0,0,(AI39-AH39)/ABS(AH39))) | AL39: =IF(AL10=0,0,AL38/AL10) | AN39: =IF(AM39="","",AM39-AL39) | AO39: =IF(AM39="","",IF(AL39=0,0,(AM39-AL39)/ABS(AL39))) | AP39: =IF(AP10=0,0,AP38/AP10) | AR39: =IF(AQ39="","",AQ39-AP39) | AS39: =IF(AQ39="","",IF(AP39=0,0,(AQ39-AP39)/ABS(AP39))) | AT39: =IF(AT10=0,0,AT38/AT10) | AV39: =IF(AU39="","",AU39-AT39) | AW39: =IF(AU39="","",IF(AT39=0,0,(AU39-AT39)/ABS(AT39))) | AX39: =B39+F39+J39+N39+R39+V39+Z39+AD39+AH39+AL39+AP39+AT39 | AY39: =SUM(C39,G39,K39,O39,S39,W39,AA39,AE39,AI39,AM39,AQ39,AU39)
A40: Labor as % of Revenue | B40: =IF(B10=0,0,B13/B10) | D40: =IF(C40="","",C40-B40) | E40: =IF(C40="","",IF(B40=0,0,(C40-B40)/ABS(B40))) | F40: =IF(F10=0,0,F13/F10) | H40: =IF(G40="","",G40-F40) | I40: =IF(G40="","",IF(F40=0,0,(G40-F40)/ABS(F40))) | J40: =IF(J10=0,0,J13/J10) | L40: =IF(K40="","",K40-J40) | M40: =IF(K40="","",IF(J40=0,0,(K40-J40)/ABS(J40))) | N40: =IF(N10=0,0,N13/N10) | P40: =IF(O40="","",O40-N40) | Q40: =IF(O40="","",IF(N40=0,0,(O40-N40)/ABS(N40))) | R40: =IF(R10=0,0,R13/R10) | T40: =IF(S40="","",S40-R40) | U40: =IF(S40="","",IF(R40=0,0,(S40-R40)/ABS(R40))) | V40: =IF(V10=0,0,V13/V10) | X40: =IF(W40="","",W40-V40) | Y40: =IF(W40="","",IF(V40=0,0,(W40-V40)/ABS(V40))) | Z40: =IF(Z10=0,0,Z13/Z10) | AB40: =IF(AA40="","",AA40-Z40) | AC40: =IF(AA40="","",IF(Z40=0,0,(AA40-Z40)/ABS(Z40))) | AD40: =IF(AD10=0,0,AD13/AD10) | AF40: =IF(AE40="","",AE40-AD40) | AG40: =IF(AE40="","",IF(AD40=0,0,(AE40-AD40)/ABS(AD40))) | AH40: =IF(AH10=0,0,AH13/AH10) | AJ40: =IF(AI40="","",AI40-AH40) | AK40: =IF(AI40="","",IF(AH40=0,0,(AI40-AH40)/ABS(AH40))) | AL40: =IF(AL10=0,0,AL13/AL10) | AN40: =IF(AM40="","",AM40-AL40) | AO40: =IF(AM40="","",IF(AL40=0,0,(AM40-AL40)/ABS(AL40))) | AP40: =IF(AP10=0,0,AP13/AP10) | AR40: =IF(AQ40="","",AQ40-AP40) | AS40: =IF(AQ40="","",IF(AP40=0,0,(AQ40-AP40)/ABS(AP40))) | AT40: =IF(AT10=0,0,AT13/AT10) | AV40: =IF(AU40="","",AU40-AT40) | AW40: =IF(AU40="","",IF(AT40=0,0,(AU40-AT40)/ABS(AT40))) | AX40: =B40+F40+J40+N40+R40+V40+Z40+AD40+AH40+AL40+AP40+AT40 | AY40: =SUM(C40,G40,K40,O40,S40,W40,AA40,AE40,AI40,AM40,AQ40,AU40)

Sheet Job Margins
A1: Job Margin Tracker
A2: Log each job below. Total Cost and Margin % calculate automatically.
A4: Job Name | B4: Customer | C4: Revenue Type | D4: What You're Charging (Contract Value) | E4: Labor Cost to Date | F4: Materials Cost to Date | G4: Sub Cost to Date | H4: Total Cost (Calculated) | I4: Margin % (Calculated) | J4: Status
A5: [Sample -- replace with your jobs] | B5: Customer 1 | C5: Commercial | D5: 150000 | E5: 35000 | F5: 28000 | G5: 15000 | H5: =IF(AND(E5="",F5="",G5=""),"",E5+F5+G5) | I5: =IF(OR(D5="",H5=""),"",IF(D5=0,0,(D5-H5)/D5)) | J5: In Progress
A6: [Sample -- replace with your jobs] | B6: Customer 2 | C6: Residential | D6: 75000 | E6: 18000 | F6: 12000 | G6: 5000 | H6: =IF(AND(E6="",F6="",G6=""),"",E6+F6+G6) | I6: =IF(OR(D6="",H6=""),"",IF(D6=0,0,(D6-H6)/D6)) | J6: In Progress
H7: =IF(AND(E7="",F7="",G7=""),"",E7+F7+G7) | I7: =IF(OR(D7="",H7=""),"",IF(D7=0,0,(D7-H7)/D7))
H8: =IF(AND(E8="",F8="",G8=""),"",E8+F8+G8) | I8: =IF(OR(D8="",H8=""),"",IF(D8=0,0,(D8-H8)/D8))
H9: =IF(AND(E9="",F9="",G9=""),"",E9+F9+G9) | I9: =IF(OR(D9="",H9=""),"",IF(D9=0,0,(D9-H9)/D9))
H10: =IF(AND(E10="",F10="",G10=""),"",E10+F10+G10) | I10: =IF(OR(D10="",H10=""),"",IF(D10=0,0,(D10-H10)/D10))
H11: =IF(AND(E11="",F11="",G11=""),"",E11+F11+G11) | I11: =IF(OR(D11="",H11=""),"",IF(D11=0,0,(D11-H11)/D11))
H12: =IF(AND(E12="",F12="",G12=""),"",E12+F12+G12) | I12: =IF(OR(D12="",H12=""),"",IF(D12=0,0,(D12-H12)/D12))
H13: =IF(AND(E13="",F13="",G13=""),"",E13+F13+G13) | I13: =IF(OR(D13="",H13=""),"",IF(D13=0,0,(D13-H13)/D13))
H14: =IF(AND(E14="",F14="",G14=""),"",E14+F14+G14) | I14: =IF(OR(D14="",H14=""),"",IF(D14=0,0,(D14-H14)/D14))
H15: =IF(AND(E15="",F15="",G15=""),"",E15+F15+G15) | I15: =IF(OR(D15="",H15=""),"",IF(D15=0,0,(D15-H15)/D15))
H16: =IF(AND(E16="",F16="",G16=""),"",E16+F16+G16) | I16: =IF(OR(D16="",H16=""),"",IF(D16=0,0,(D16-H16)/D16))
A18: SUMMARY
A19: Totals / Averages | C19: =COUNTA(A5:A16) | D19: =SUM(D5:D16) | H19: =SUM(H5:H16) | I19: =IF(D19=0,0,(D19-H19)/D19)

Sheet Cash Flow
A1: 13-Week Cash Flow Forecast
A2: Enter expected inflows and outflows each week. Ending cash rolls forward automatically.
B4: Week 1 | C4: Week 2 | D4: Week 3 | E4: Week 4 | F4: Week 5 | G4: Week 6 | H4: Week 7 | I4: Week 8 | J4: Week 9 | K4: Week 10 | L4: Week 11 | M4: Week 12 | N4: Week 13
A5: Starting Cash | B5: =Assumptions!$B$49 | C5: =B12 | D5: =C12 | E5: =D12 | F5: =E12 | G5: =F12 | H5: =G12 | I5: =H12 | J5: =I12 | ... N5: =M12
A6: MONEY COMING IN (INFLOWS)
A7: Collected from Customers (AR)
A8: New Revenue Expected
A9: Total Inflows | B9: =B7+B8 | C9: =C7+C8 | D9: =D7+D8 | E9: =E7+E8 | F9: =F7+F8 | G9: =G7+G8 | H9: =H7+H8 | I9: =I7+I8 | ... N9: =N7+N8
A10: MONEY GOING OUT (OUTFLOWS)
A11: Payroll
A12: Materials
A13: Subcontractors
A14: Fixed Costs (from Assumptions) | B14: =Assumptions!$B$40/4.33 | C14: =Assumptions!$B$40/4.33 | D14: =Assumptions!$B$40/4.33 | E14: =Assumptions!$B$40/4.33 | F14: =Assumptions!$B$40/4.33 | G14: =Assumptions!$B$40/4.33 | H14: =Assumptions!$B$40/4.33 | I14: =Assumptions!$B$40/4.33 | ... N14: =Assumptions!$B$40/4.33
A15: Total Outflows | B15: =B11+B12+B13+B14 | C15: =C11+C12+C13+C14 | D15: =D11+D12+D13+D14 | E15: =E11+E12+E13+E14 | F15: =F11+F12+F13+F14 | G15: =G11+G12+G13+G14 | H15: =H11+H12+H13+H14 | I15: =I11+I12+I13+I14 | ... N15: =N11+N12+N13+N14
A16: Net Cash Flow | B16: =B9-B15 | C16: =C9-C15 | D16: =D9-D15 | E16: =E9-E15 | F16: =F9-F15 | G16: =G9-G15 | H16: =H9-H15 | I16: =I9-I15 | ... N16: =N9-N15
A17: Ending Cash | B17: =B5+B9-B15 | C17: =C5+C9-C15 | D17: =D5+D9-D15 | E17: =E5+E9-E15 | F17: =F5+F9-F15 | G17: =G5+G9-G15 | H17: =H5+H9-H15 | I17: =I5+I9-I15 | ... N17: =N5+N9-N15
